Workbook

Sheet Introduction
A1: Heading for Change Scorecard Tool
G2: Note: Last updated October 2025
A7: The Heading for Change ("HfC") Scorecard is used as an important Screening and Due Diligence tool to evaluate funds against the key metrics underpinning the HfC investment thesis and investment criteria. It is used throughout the HfC investment process: (i) To support pipeline mapping and compare multiple funds across similar portfolio criteria or characteristics (i.e. regional or sector-based market mapping), in order to identify the opportunity that best aligns with HfC's strategy and portfolio construction objectives. (ii) As an initial screening tool to determine whether a pipeline fund meets HfC investment criteria and is eligible for a potential investment, as well as identifying potential areas for further due diligence. (iii) During due diligence as a final scoring tool to confirm that the fund meets HfC investment criteria (yes/no) and identify possible areas for post-investment support. The HfC Scorecard is intended to be a directional tool to support investment decision-making, that assesses both quantitative and qualitative metrics. It is one part of HfC's holistic investment and due diligence process (which also inludes HfC's Climate & Gender Due Diligence Questionnaire, fund and financial due diligence, and investor and portfolio company reference calls) and, as such, it is not intended to be used on a stand-alone or absolute basis. The Scorecard builds on the groundwork of many gender and climate leaders in the field - for example, Sweef Capital ROI as it relates to gender and inclusion and Project Drawdown on the climate side. As such, we build our framework upon these well-established tools and approaches, enabling users to assess intentionality, execution, and areas for growth. This tool is designed to be non-prescriptive, with the intent that users take the aspects which make the most sense for their strategy and process, and use it to enhance existing climate and/or gender analysis with the dimensions of the HfC scorecard that suit their purpose. It has many potential use cases that could enhance investment processes, including screening, due diligence, investment committees and/or portfolio performance monitoring. Users are invited to question, explore, and apply what resonates with their own theory of change, investment thesis, or strategic priorities. We encourage users to approach the Scorecard with an open, curious, and learning mindset, especially in recognition of the nascent and evolving nature of climate and gender investing. As the field grows and new insights and data become available, we anticipate that the Scorecard will continue to iterate and adapt. In addition, the Scorecard should always be used in context. It is essential to consider regional differences, local nuances, and broader societal structures and biases that may shape how climate and gender dynamics show up in different geographies or sectors. While our aim has been to make the tool as clear, tangible, and objective as possible, there will inevitably be a degree of subjectivity in assessing impact-oriented funds. Finally, while the Scorecard includes criteria related to Impact Measurement & Management (IMM) — specifically regarding the degree to which a fund creates, measures, reports and acts upon on climate and/or gender impact — please note, that for our process, it is not used as part of a formal IMM system for monitoring portfolio performance post-investment. Its purpose is to inform pre-investment decision-making, rather than serve as a comprehensive impact tracking and management framework.
A9: Using the Criteria & Scorecard:
A10: The "Scorecard" tab contains an overview and explanation of each of the HfC criteria across 5 categories:
A11: 1) Climate/Nature & Biodiversity 2) Breadth & Depth of Gender 3) Climate & Gender Integration 4) Organization & Team 5) Fundraising, Fund Terms, Structure & Risk
A17: Scoring: The first five categories are scored on a scale of 1 to 5. The minimum score to be eligible for an HfC investment is a 3. Scoring Guidelines: Scoring guidelines are provided for most criteria and reflect HfC’s priorities, emphasizing the factors most relevant to the investment thesis, as well as the specific characteristics of funds at the climate and gender nexus that we believe to be most critical for achieving strong impact and financial outcomes (for e.g. place-based teams with local representation advancing fit-for-purpose and gender-smart climate solutions). Individuals or organizations adopting this scorecard are encouraged to tailor the scoring framework to their own impact goals, return targets, and broader portfolio construction considerations (i.e. North American funds vs Emerging Markets funds). Scorecard Weighting: In the scorecard, each score is weighted based on the priorities HfC has identified within a respective section. These weighted scores contribute to the section’s total, which is further weighted in the Scorecard Summary to produce a final overall score. As climate and gender are central to our investment thesis, the collective weight of these dimensions is 70% and forms a major part of our due diligence and analysis. As with the scoring guidelines, users are encouraged to adjust the weights of individual sections and the summary to reflect their specific priorities, impact goals, and investment mandates. Please note that for our scoring purposes scoring begins at 1, rather than 0 therefore non-compliant funds do score 1, once weighting is complete. Weighting systems should be appropriately utilised at section and scorecard level. How & When to Use the Scorecard: The scorecard is not intended to provide a definitive “go/no-go” decision on an investment. Instead, it serves as a tool to compare opportunities side-by-side within similar geographies or investment theses, and to provide a high-level snapshot of a fund, highlighting gaps and areas for deeper exploration during due diligence or areas for post-investment support. At HfC we do not use the tool as a baseline for impact measurement and management, but other users could leverage the baseline score and track progress over the lifecycle of the investment, if that aligns better with their processes in place. It is also important to contextualize the score within the broader cultural, regional, sectoral, or structural backdrop that the fund operates within. We have found that nuance is critical in this space, as is meeting the market where it is, so that we can champion the most catalytic changemakers addressing the unique set of gender and climate challenges of a particular region or sector.

Sheet Scorecard
A1: Heading for Change Investment Scorecard
A3: Fund Name
A4: Assessment Date
A5: Prepared By
A8: I. Climate / Nature & Biodiversity | D8: Score | E8: Description | F8: Explanation for scoring 1 - 2 | G8: Explanation for scoring 3 -5
A9: 1a | B9: Thesis & Strategy: Climate/Nature & Biodiversity | C9: 0.35 | D9: 1 | E9: To qualify as Climate/Nature, funds must have or target a minimum % of investments into Climate and/or Nature related themes that seek to support climate mitigation, adaptation and resilience actions. Investment themes include (but are not limited to): Industrial Decarbonization, Renewable Energy/Energy Transition, Resource Efficiency, Energy Efficiency, Green Manufacturing, Green Mobility, Circularity, Sustainable & Regenerative Agriculture, Ocean Ecosystems, Biodiversity, Nature-Based Solutions, Sustainable Forestry, Climate resilient financial solutions etc.). Multi-thematic funds can be considered if the non-climate/nature deals are in high impact sectors (health, education, financial services) and apply a climate/nature lens to those investments (i.e. installing rooftop solar on a hospital or pharmacy). | F9: 1 = The fund does not invest in climate/nature and does not intend to 2 = Less than 51% of portfolio commitments in climate/nature. The non-climate/nature deals are not in high-impact sectors and there is no intention to add a climate/nature lens to the non-climate/nature deals (i.e. the opportunistic fund with i.e. a 25% allocation to climate/sustainability) | G9: 3 = More than 51% of the portfolio commitments in climate/nature, in mostly high impact sectors. The non-climate/nature deals do not have a climate lens but the fund is open and interested to incorporate one with support 4 = More than 51% of investments in climate/nature, non-climate deals are in high-impact sectors and apply a climate-lens to non-climate deals 5 = >75% of investments in climate/nature
A10: 1b | B10: Thesis & Strategy: Near-Term, Material Solutions; Replicable Solutions; Climate Vulnerable and/or Place-Based | C10: 0.3 | D10: 1 | E10: Funds are scored according to the degree their investment strategy and thesis is focused on investing in solutions, innovative business models or projects with near-term (within 10 years), material impact (quantitative & qualitative) and which can be replicated and/or scaled across regions/geographies. Also considered is the degree to which a fund is investing in climate vulnerable places, people and/or regions that are especially critical to climate resiliency, i.e. investing in the blue economy of island nations vulnerable to flood risk or investing in refugees tackling climate change; and/or place based solutions that have been locally designed with community-centered, context-specific and participatory approaches. | F10: 1 = The investment thesis & strategy does not consider whether solutions are near-term, material, and/or scalable; nor in climate vulnerable people or places 2 = The investment thesis & strategy has limited consideration for solutions which are near-term, material, scalable or in climate vulnerable people or places and there is limited or inconsistent underpinning in policies and processes | G10: 3 = The investment thesis & strategy considers one or more of: near-term, material, scalable and/or climate vulnerable people & places, has some degree of codification in their strategy & processes and is open to receive support to further embedding and underpinning 4 = The investment thesis & strategy actively considers one or more of: near-term, material, scalable solutions and/or in climate vulnerable people or places in their investment thesis and are integrated into the approach. 5 = The fund's Theory of Change, investment thesis and strategy fully align with solutions that are near-term, material and scalable and/or in climate vulnerable people or places, are well articulated and underpinned in their marketing materials and supported by internal policies, processes and reporting
A11: 1c | B11: Climate Taxonomy & Impact Measurement, Management & Monitoring | C11: 0.2 | D11: 1 | E11: The fund has a robust climate impact measurement, management & monitoring system, including appropriate policies, processes and people. The fund has adopted existing climate/nature taxonomy, including but not limited to: TCFD, TNFC, SBTi, Project Drawdown, Paris Agreement, Net Zero, Project Frame and/or UN SDGs & sub-goals. Climate impact reporting is used for internal purposes (i.e. investment decision-making, monitoring, reporting, incentivization) as well as external stakeholder communcation and reporting. Where possible, the fund collects gender-disaggregated climate data on its investments. | F11: 1 = The fund does not, and has no plans to track, measure or report on global standards and metrics 2 = The fund tracks and measures some standards, but not consistently or aligned with standards | G11: 3 = The fund tracks and measures some standards, however commits to developing measurement and reporting systems that better align with global standards (but may require support to do so) 4 = The fund tracks and measures on global standards and metrics in its portfolio and uses this data for portfolio management and/or adhoc LP reporting but no external/limited impact reporting data is made available 5. The fund has a best-in-class system that tracks, measures and reports on global climate standards and metrics to enhance porfolio performance, to align with LP reporting requirements, and provide regular external impact reports
A12: 1d | B12: Just Transition | C12: 0.15 | D12: 1 | E12: A Just Transition seeks to ensure that the substantial benefits of a green economy transition are shared widely while also supporting those who stand to lose economically. It means investing in a way that is as fair and inclusive as possible, creating decent opportunities, sustained growth and leaving no one behind. (i.e. creating greater sustainable wealth for communities; improving access to climate-related goods & services, etc). The fund is able to articulate and demonstrate a clear strategy to ensuring a Just Transition with the ability to define a set of stategic, clear and time-bound actions at the portfolio and fund level that seeks to ensure the benefits of a transition to a green economy are shared widely, and where lived experience and a focus on proximity is baked in, all the way from the design to the outcomes. | F12: 1 = The fund does not have a Just Transition lens, has no understanding and no intention of incorporating one 2 = The fund does not have a Just Transition lens, has some limited understanding and policies, but they are not consistent or aligned with standards | G12: 3 =The fund does not have a Just Transition Lens, has some understanding, sees the benefit and applicability to their strategy and is interested to receive support to incorporate one 4 = The fund has a Just Transition Lens with a clear formulation of its impact intention into the Theory of Change, however lacks formalization, operationalization and measurement/reporting capabilities, but is willing to incorporate 5 = The fund has a clearly articulated and well thought out Just Transition Lens, linked to their Theory of Change, which is embedded in their processes, procedures and people, with clear impact objectives and time-bound actions in place. It is able to engage in nuanced discussions in terms of how their Just Transition approach is practiced at both the fund and portfolio level
C13: =SUM(C9:C12) -> 1
B14: Total Subscore | C14: 0.3 | D14: =SUMPRODUCT(D9:D12,C9:C12) -> 1
A16: II. Breadth & Depth of Gender | D16: Score | E16: Description | F16: Explanation for scoring 1 - 2 | G16: Explanation for scoring 3 -5
A17: 2a | B17: Gender Lens | C17: 0.3 | D17: 1 | E17: Gender lens investing is the integration of gender analysis alongside financial analysis , incuding new or existing investment processes for better social and financial outcomes. The fund must have an explicit gender lens or a gender and broader diversity and inclusion lens as part of their investment strategy and thesis, spanning baseline representation of women/underserved groups at fund and portfolio levels as well as policies, processes and guidelines to support equity in the workplace. Beyond representation and policies, funds should demonstrate that they integrate a broader gender lens in their approach, activities and demonstrate intentionality and authenticity in other, more qualitative ways such as: i) outlining time-bound commitments to enact further gender-smart actions; ii) integrating gender-smart approaches across the investment process to address unconscious bias ; iii) bringing in gender expertise as part of market analysis, due diligence and decision-making; iv) examining and improving their own processes and actions through a power lens and other such activities; v) incorporating gender/racial/ethnic diversity in the analysis and set-up of the entire value chain of fund admin and support, including suppliers, vendors, legal and administrative support, etc. | F17: 1 = The fund has no explicit gender or inclusion lens, and no intention of incorporating one 2 = The fund is able to verbally articulate the importance of a gender and inclusion lens but does not have an intentional thesis, strategy, or defined set of actions it priortizes to support this agenda | G17: 3 = The fund has a defined strategy and/or position on gender and/or inclusion, however currently has no tangible actions at the fund or portfolio level, though are commited to developing an intentional approach with defined set of actions it priortizes to support this agenda 4 = The fund has a clear formulation of its gender lens intention into a Theory of Change/impact strategy or investment thesis and has some adhoc priorties or timebound actions that it applies at fund or portfolio level, althought not consistently (potentially for strategic reasons related to market bias) 5 = The fund has a clear gender investing strategy, including investment thesis, and actively integrates gender-smart practices across its investment process, including key areas such as risk assessments, gendered due diligence, engagement in gender-specific portfolio monitoring and may use incentives, accountability mechanisms and/ or TA to enhance gender outcomes at porfolio level. The fund has its gender position clearly articulated within its marketing materials and externally positions itself as a gender lens fund. The fund creates opportunities for gender and inclusion within the fund, across its portfolio and the supply chain
A18: 2b | B18: Women's Ownership & Leadership | C18: 0.3 | D18: 1 | E18: The fund must meet one criteria for Entrepreneurship/Ownership and one criteria for Leadership: - Entrepreneurship/Ownership: (i) is founded by a self-identifying woman OR (ii) at least 30% women-owned - Leadership: (i) at least 50% of the fund management team are women and/or from under-represented backgrounds, OR (ii) 25% of the fund management team are women if other management team members are diverse OR (iii) at least 50% of women on the IC, Board or other decision-making body. At portfolio company level, at least 30% of the portfolio companies must meet one of the following criteria: - Entrepreneurship/Ownership: is founded by a woman OR at least 30% owned by women - Leadership: 30% of senior management team are women - Employees and Supply Chain: 40% of the workforce and/or supply chain are women - Consumers: Products or services disproportionately or specifically benefit women In addition, qualifying funds and portfolio companies must also demonstrate minimum governance and accountability requirements. Guidance on this aspect can be found under the updated 2X Criteria, as well as by looking at gender-smart policies and practices in place within the fund and the portfolio companies). Also, Sweef Capital Gender ROI™ (Gender ROI™) tool provides clear and common language around gender, including the importance of clear systems and processes with which to translate aspirations into superior financial performance and positive social, economic and environmental impact. Note: Some of these thresholds, particularly as it relates to the 2X Criteria were adjusted to reflect current and prevailing market dynamics | F18: 1 = No gender diversity in founding team, ownership or leadership at fund or portfolio company level 2 = Some diversity present but does not meet criteria at fund and/or portfolio company level | G18: 3 = Fund meets criteria for entrepreneurship/ownership OR Leadership at fund level and is open to support in bridging the gap and setting time-bound targets at both fund and portfolio company level 4 = Fund meets criteria for entrepreneurship/ownership and fund management team, but not IC/decision-making, and is open to support and setting time-bound targets on advancement 5 = Fund exceeds criteria for entrepreneurship/ownership & leadership at both the fund and portfolio company level and has clear and stated intention, targets and commitments to enact
A19: 2c | B19: Gender & Inclusion Principles & Impact Measurement, Management & Monitoring | C19: 0.2 | D19: 4 | E19: The fund leverages globally recognised tools such as the 2X Criteria(harmonised with IRIS+, UN Women's Women Empowerment Principles (WEPs) etc), Criterion Institute's Process Standards, Sweef's ROI tool and others, and aligns with broad criteria and entry points for investing with a gender lens. The fund actively tracks, measures and reports on gender standards and metrics in its portfolio. Gender impact reporting is used for internal purposes (i.e. strategy, investment decision-making, monitoring, reporting, incentivization) as well as external stakeholder communcation and reporting | F19: 1 = The fund does not, and has no plans to track, measure or report on global gender standards and metrics 2 = The fund tracks and measure some standards but this is either not done consistently nor is it aligned with global standards | G19: 3 = The fund tracks and measure some standards, however committs to developing measurement and reporting systems that better align with global standards (but may require support to do so) 4 = The fund tracks and measures on global standards and metrics in its portfolio and uses this data for portfolio management and/or adhoc LP reporting but no external impact reporting data is made available 5. The fund has a best-in-class system that tracks, measures and reports on global standards and metrics to enhance porfolio performance, to align with LP reporting requirements, and provide regular external impact reports
A20: 2d | B20: Justice, Equity, Diversity & Inclusion | C20: 0.2 | D20: 5 | E20: Justice, Equity, Diversity and Inclusion ("JEDI") promotes the incorporation of gender, racial and ethnic justice in global investment decision making and contributes toward facilitating the broader transition towards a more participatory, equitable and sustainable financial ecosystem. The fund demonstrates diversity beyond gender in fund leadership and decision making, with awareness of intersectionality, power dynamics and how existing structures are being challenged/changed to allow broader and better access to underestimated groups and communities. The fund also actively demonstrates an internal commitment to supporting team members to have access to opportunities and advancement to leadership and decision-making positions and in overall succession and growth plans, as well as in tackling barriers to achieving their full potential. The fund demonstrates a commitment to encouraging and driving these same practices in their portfolio companies, and other relevant stakeholders (such as in the supply chain, vendors). | F20: 1 = No explicit mention, implicit understanding of JEDI principles and poor representation of diverse groups "other than women" in fund structures. No active plans or intentions to actively create opportunities for equity and inclusion in the fund 2 = The fund is able to verbally articulate the importance of a broader JEDI lens but does not have an intentional thesis, strategy, or defined set of actions it priortizes to support this agenda | G20: 3 = The fund has a defined strategy and/or position on JEDI, however currently has no tangible actions at fund or portfolio level though are commited to developing an intentional approach with defined set of actions it priortises to support this agenda. 4 = The fund has a clear formulation of its JEDI intention into a Theory of Change, impact strategy or formulated policies and engages in some adhoc opportunities, priorities or timebound actions that it applies at fund or portfolio level (although not consistently) 5 = The fund has a clear JEDI strategy including investment thesis and actively integrates considerations across its investment process, has or is actively creating and advancing a diverse workplace at fund level, engages in broader stakeholder acitvism, and takes actions with its porfolio companies to enhance JEDI outcomes
C21: =SUM(C17:C20) -> 1
B22: Total Subscore | C22: 0.2 | D22: =SUMPRODUCT(D17:D20,C17:C20) -> 2.4
A24: III. Climate & Gender Integration | D24: Score | E24: Description | F24: Explanation for scoring 1 - 2 | G24: Explanation for scoring 3 -5
A25: 3a | B25: Women as Agents of Change in Investment Thesis | C25: 0.25 | D25: 4 | E25: The fund considers the role and impact of women, as well as a broader gender and diversity lens, in their climate/nature investment thesis. A few examples of how the climate and gender integration is demonstrated include: - Considering the ways in which women, girls and other marginalised communities are disproportionately impacted by the key climate/nature-related risks the thesis seeks to address; considering the ways in which there are potential risks to the fund’s investment strategy, process or performance by not intentionally including/focusing on women & girls and other marginalised communities - Indentifying climate-smart products or services which are better for women and gender equality more broadly, identifying areas where women's unique expertise/experience could be leveraged (in terms of product design, leadership, as consumers) and - Considering ways in which the inclusion of women as change agents contributes to improved financial, climate and social outcomes | F25: 1 = No integration and no evidence of willingness to include 2 = No integration, some evidence and willingness to include | G25: 3 = Early integration (i.e. the fund manager can speak to the integration of a gender lens and the role of women in the climate value chain/creating improved climate/financial outcomes, but it is not embedded in nor has it informed the development of their thesis nor approach) AND/OR strong intentionality to integrate 4 = Partially integrated thesis (i.e. the role of women is implicitly embedded in the investment thesis, but is not included explicitly in fund materials and/or is not fully considered across all aspects of the thesis - for example, they consider how women and girls might be disproportionately impacted by climate risks, but not how women's engagement in the climate solutions value chain can improve outcomes) 5 = Fully integrated thesis and embedded in strategy and processes
A26: 3b | B26: Women as Agents of Change in the Investment Process | C26: 0.2 | D26: 4 | E26: The fund considers the role that women (could) play as agents of change, as well as a broader gender and diveristy lens, in some or all aspects of their investment process, including opportunity mapping & sector identification, deal sourcing, screening and DD and/or post investment support. | F26: 1 = No consideration and no evidence of willingness to integrate into the investment process 2 = No consideration, some evidence and willingness to intergate into the investment process | G26: 3 = Early integration (i.e. the fund manager can speak to the gender lens and the role of women in the climate value chain/creating improved climate/financial outcomes, but it is not embedded, nor has it informed the development of their thesis nor approach) AND/OR there is strong intentionality to integrate 4 = Partially integrated thesis (i.e. the gender lens and role of women is implicitly embedded in the investment thesis, but is not included explicitly in fund materials and/or is not fully considered across all aspects of the thesis--for example, they consider how women and girls might be disproportionately impacted by climate risks, but not how women's engagement in the climate solutions value chain can improve outcomes) 5 = Fully integrated thesis and embedded in strategy and processes
A27: 3c | B27: Eliminating Barriers to Women's Active Participation as Change Agents | C27: 0.15 | D27: 3 | E27: The fund is aware of the barriers that women and underrepresented groups face to gaining equal access to jobs/roles in the industries of focus, and is in some way contirbuting to the elimination of these barriers (i.e. providing technical support, developing relationships with other stakeholders/thought leaders, bringing in diverse voices such as women's rights organisations, other local and proximate community actors, etc). | F27: 1 = No evidence of awareness nor action to eliminate barriers 2 = No current action, some evidence of awareness and willingness to develop actions and eliminate barriers | G27: 3 = Strong evidence of intent/willingness to address barriers AND early signs of action (for e.g. consulting with community actors and grassroots organizations to understand barriers/challenges) 4 = Clear evidence of both awareness and some degree of action to eliminate barriers for women and under-represented groups (for e.g. ongoing development of a strategy or plan of action to support portfolio in hiring/retaining women, particularly those from under-represented groups ) 5 = Participatory, collaborative, evidence-based actions to eliminate barriers for women and under-represented groups are clearly and well integrated into fund processes and/or strategy
A28: 3d | B28: Transformational Change for Women | C28: 0.2 | D28: 3 | E28: The fund is catalysing transformational change for women, with a focus on improved outcomes for the lives and livelihoods of women, and is on a journey of moving along gender-aware to positive and transformative gender equality outcomes. It could also be leveraging gender-disaggregated data to improve climate outcomes, and integrating local and proximate voices who are at the forefront of climate change and climate action, into product design/delivery/follow ups. | F28: 1 = No evidence of transformational change for women, nor of a willigness to considering improved outcomes for women in the thesis or investment strategy and process 2 = No evidence of transformational change for women, but some evidence of a willigness to considering improved outcomes for women | G28: 3 = Early signs of considering transformational change for women is embedded in some aspects thesis, strategy and process (for e.g some consultations with grassroots orgs) 4 = Transformational change for women is partially embedded in all aspects of thesis, strategy and process (for e.g all new product design occurs in partnership with community actors and climate resilience outcomes are co-created) 5 = Transformational change for women is deeply embedded in all aspects of thesis, strategy and process (for e.g. the investment Theory of Change was co-created with all relevant stakeholders, there are diverse voices involved in investment decision making, including women's rights organisations, and product design to sales is all built with end consumers and outcomes in mind
A29: 3e | B29: Scaling Products and Services by/for Women | C29: 0.2 | D29: 3 | E29: At least 30% of the portfolio/pipeline must demonstrate that women play an outsized role in developing, manufacturing, distributing, selling and/or buying products or services to tackle climate-related challenges. This includes: - Promoting or accelerating women entrepreneurs and leaders to advance climate action - as idea generators, product or service designers or good leaders - Creating quality green jobs or opportunities for women in the workforce or supply chain, and/or include intersections around care economy - Designing or adapting products and services which a) have been designed including women and other under-represented groups, b) improve women’s access to, usage and benefit from climate-smart solutions (c) address gender gaps or inequalities and contribute to greater economic empowerment, enhanced resilience, better livelihoods and more or d) also consider unintended consequences/how aspects of gender-based violence may intersect with/impact goods and services | F29: 1 = Women do not appear to play a role in the climate value chain in any of the portfolio companies/pipeline 2 = Women play a role in the climate value chain in less than 30% of the portfolio companies/pipeline and there is limited or no evidence of an intent to increase this number either in subsequent investments or in helping existing portfolio companies to engage women in the development and scaling of climate solutions | G29: 3 = Women play a role in the climate value chain in less than 30% of the portfolio companies/or pipeline. AND there is strong evidence of an intent to increase this number either in subsequent investments or in helping existing portfolio companies to engage women in the development and scaling of climate solutions 4 = Women play a role in the climate value chain in at least 50% of the portfolio companies 5 = Women play a role in the climate value chain in 100% of the portfolio companies
C30: =SUM(C25:C29) -> 1
B31: Total Subscore | C31: 0.2 | D31: =SUMPRODUCT(D25:D29,C25:C29) -> 3.45
A33: IV. Organization & Team | D33: Score | E33: Description | F33: Explanation for scoring 1 - 2 | G33: Explanation for scoring 3 -5
A34: 4a | B34: Track Record | C34: 0.3 | D34: 4 | E34: Fund team has either a proven & verifiable investment/exit track record relevant to the fund's investment strategy and/or sufficient proxies( i.e. angel / warehouse investments/other financial sector experience). For newer funds/managers, we will align with the Due Diligence 2.0 Commitment and “will evaluate members of the investment and leadership team based on past experience, investment sourcing capabilities, domain expertise, operational value add, as well as assess prior track records in related or relevant work. To the extend the manager is using partner firms to complement their skillsets, the relevant experience and track records of said partners will be evaluated. | F34: 1 = No relevant prior investment or operational track record in climate or gender or poor long term performance. The fund underperforms peers and benchmarks in the same vintage and has not delivered the targeted impact 2 = Moderate relevant past performance in climate or gender associated to very few outliers with a high loss ratio, and the fund has not delivered the targeted impact | G34: 3 = Relevant and demonstrated investment track record in climate or gender but limited distributions or realizations and too early to gauge impact 4 = Solid and relevant track record, some distributions/exits with clear demonstration of value add and early impact achievements 5 = Strong, long-term/cycle tested and relevant climate & gender investment track record with low loss ratio and clear demonstration of impact
A35: 4b | B35: Team History, Cohesion and Complementarity & Culture | C35: 0.25 | D35: 3 | E35: The team has demonstrated a history of working together or collaborating as co-investors, co-founders or partners in a previous venture, etc. In addition, fund managers demonstrate differentiated and complementary skill sets and backgrounds. The team fosters a strong and gender-smart culture, leading by example in the way in which they create an inclusive workplace for all. | F35: 1 = New or first time fund and team with no prior history of working together and no/limited prior relevant climate or gender investment experience. No inclusive culture 2 = New or first time team with some prior working history and some climate or gender experience. Moderately inclusive culture with room for improvement | G35: 3 = New or first time team with prior and relevant history, backgrounds and complementary climate and gender experience OR emerging team (c. 3 - 5 years together) who worked on predecessor fund and have complementary backgrounds and skill sets, with a commitment to developing and fostering an inclusive culture 4 = Experienced, well-resourced and cohesive team (c. 5 - 7 years together) with a good blend of background and inclusive culture and low turnover 5 = Highly experienced, stable and cohesive team working together over a long period (+10 years) with complementary backgrounds and skill-sets, and a strong & inclusive culture
A36: 4c | B36: Team Location & Composition & Diversity | C36: 0.25 | D36: 5 | E36: Team members are primarily based in the markets where they are active and have a balanced/diverse team including investment professionals from the markets where they are active. | F36: 1 = Team has no local representation and is not present in the markets in which they invest 2 = Team has some diversity and representation of and presence in the markets in which they invest but not in senior or decision making roles | G36: 3 = Team location and representation are satisfactory in terms of relevant local/in country time spent 4 = GPs are not based locally, but spend enough time on the ground and other senior investment team members are on the ground 5 = Key investment team members or partners are based locally where investments are made or on the ground often enough, deeply immersed in local community and also bring in relevant local partners and stakeholders to fill gaps
A37: 4d | B37: Alignment of Interest | C37: 0.2 | D37: 4 | E37: Carried interest is broad based, well split and spread and appropriately reflects an individual's role/contribution to the success of the fund; when appropriate, there is a relevant, realistic & material GP commit to help appropriately align incentives. | F37: 1 = Carried interest is concentrated with partner(s) with no expectation to share broadly and/or no GP commit 2 = Carried interest is concetrated with several partners, is not transparent and there is a low/non-material GP commit | G37: 3 = Carried interest is more broadly and appropriately spread in the investment team with a modest GP commit and a commitment to increase in future funds 4 = Carried interest is well spread across the entire team and firm with an appropriately aligning and incentivizing GP commit 5 = Carried interest is broad based, well spread and transparently communicated across the entire team and firm with a material / "above market" GP commit
C38: =SUM(C34:C37) -> 1
B39: Total Subscore | C39: 0.2 | D39: =SUMPRODUCT(D34:D37,C34:C37) -> 4
A41: V. Fundraising, Fund Terms, Structure & Risk | D41: Score | E41: Description | F41: Explanation for scoring 1 - 2 | G41: Explanation for scoring 3 -5
A42: 5a | B42: Fundraising Status | C42: 0.25 | D42: 3 | E42: The fund is currently fundraising and is on track for a final close within the next 12-18 months at a fund size which has been deemed at least mininmally viable to retain the team and properly execute the envisaged investment strategy. | F42: 1 = Lengthy fundraising (+18 months) with no/little fundraising traction and no visibility on a first close 2 = Lengthy fundraising (+12 months), some traction but unlikely to achieve a first close in the next 12 months | G42: 3 = Some early fundraising traction (DD / soft / conditional commitments) with moderate but acceptable fundraising risk, where investors believe they can acheive a minimum viable fund size within the next 12 months 4 = Hard or soft commitments secured and the fund is on-track for a close at or above the minimum viable fund size within the next 12 months 5 = First close at/above minimum viable fund size with good visibility to reach fund target/hard cap within 12 months
A43: 5b | B43: Anchor Investor | C43: 0.25 | D43: 4 | E43: The fund must have secured a commitment from an anchor investor or is in advanced talks with an anchor investor (or group of investors) to commit 5-10% of the target fund size and has line of sight to a first close, if one has not already occurred. | F43: 1 = No anchor and no early commitments 2 = Early commitments less than 10% | G43: 3 = Soft commitments secured c. 10%, no anchor investor(s) but good fundraising pipeline and in discussion with potential anchor(s) 4 = Anchor commitment secured c. 10-20% of fund size and good fundraising pipeline/visibility of like-minded and aligned investors 5 = Anchor commitment(s) secured c. 20% of fund size and strong hard and soft commitments from other aligned and like-minded investors
A44: 5c | B44: Fund Terms & Structure | C44: 0.1 | D44: 4 | E44: General fund terms (i.e. management fee, hurdle, carried intertest, GP commit, investment period, fund life) are reasonable, acceptable and in line with market standards and/or are appropriate given the fund structure or asset class. | F44: 1 = Fund terms off-market, inappropriate for investment strategy and asset class, and/or represent legal risk to the investor, and no willingness to change 2 = Mixed terms/ less appropriate terms and unwilling to change | G44: 3 = Mixed terms with area for improvement and willingness to adjust/align with market acceptable terms 4 = Largely in line with the market and appropriate for the investment strategy and asset class 5 = Fully in line with/better than market standard
A45: 5d | B45: Financial Viability | C45: 0.2 | D45: 3 | E45: A cursory review of fund financials demonstrates credible and realistic assumptions by the fund manager and is consistent with return expectations for the asset class, sector of focus and investment strategy. Furthermore the fund manager has sufficient income (from either management fee or working capital) to sustain the fund manager and team for the coming 12 - 24 months and there is comfort and confidence about the mid-long term viability of the firm and fund. | F45: 1 = The fund has no financial model/projected returns and/or they are unrealistic and inappropriate for the investment strategy or asset class. Fund manager is not viable without working capital and/or achieving a minimum viable fund size 2 = Basic model but assumptions are unrealistic and the investment strategy is not expected to return capital / be sustainable. Fund manager viability at risk depending on securing working capital and/or achieving a minimum viable fund size | G45: 3 = Basic fund model/projections with at least a capital preservation expected in the downside scenario. Moderate short term financial viability of the manager although achieving a minimum viable fund size is critical to maintain the team 4 = Fund model/target returns are in line with the market and expected to achieve at least the hurdle rate. Solid financial viability and runway with ability to keep the team even if there are fundraising delays 5 = Fund model/projections are well underpinned and deemed reasonable, realistic and appropriate for the investment strategy and asset class with high expectations on its ability to deliver strong financial and impact outcomes at or above target. Fund manager is financially viable, has adequate cash runway to properly manage the fund and maintain the team
A46: 5e | B46: Risk Assessment | C46: 0.2 | D46: 3 | E46: A cursory review of legal, operational and technical risks does not indicate that there are risks that would meaningfully impact the investor's investment mandate or reputation or would have an adverse impact on projected financial and impact outcomes. | F46: 1 = Material risks exist which cannot be appropriately mitigated 2 = Material risks exist with some, but insufficient, mitigation | G46: 3 = Some know and unknown risks which are partially mitigated but acceptable 4 = Some risks exist but they are well identified and mitigated 5 = Few risks all of which are well understood, accepted and mitigated
C47: =SUM(C42:C46) -> 1
...

Sheet Scoring Summary
A1: Scorecard Scoring Summary
A3: Criteria | B3: Weight | C3: Score
A4: =Scorecard!A8 -> I. Climate / Nature & Biodiversity | B4: =Scorecard!C14 -> 0.3 | C4: =B4*Scorecard!D14 -> 0.3
A5: =Scorecard!A16 -> II. Breadth & Depth of Gender | B5: =Scorecard!C22 -> 0.2 | C5: =B5*Scorecard!D22 -> 0.48
A6: =Scorecard!A24 -> III. Climate & Gender Integration | B6: =Scorecard!C31 -> 0.2 | C6: =B6*Scorecard!D31 -> 0.69
A7: =Scorecard!A33 -> IV. Organization & Team | B7: =Scorecard!C39 -> 0.2 | C7: =B7*Scorecard!D39 -> 0.8
A8: =Scorecard!A41 -> V. Fundraising, Fund Terms, Structure & Risk | B8: =Scorecard!C48 -> 0.1 | C8: =B8*Scorecard!D48 -> 0.335
A9: TOTAL | B9: =SUM(B4:B8) -> 1 | C9: =SUM(C4:C8) -> 2.605

Sheet Scorecard Components
B1: Scorecard Components
B3: =Scorecard!A8 -> I. Climate / Nature & Biodiversity | C3: =Scorecard!B9 -> Thesis & Strategy: Climate/Nature & Biodiversity
C4: =Scorecard!B10 -> Thesis & Strategy: Near-Term, Material Solutions; Replicable Solutions; Climate Vulnerable and/or Place-Based
C5: =Scorecard!B11 -> Climate Taxonomy & Impact Measurement, Management & Monitoring
C6: =Scorecard!B12 -> Just Transition
B8: =Scorecard!A16 -> II. Breadth & Depth of Gender | C8: =Scorecard!B17 -> Gender Lens
C9: =Scorecard!B18 -> Women's Ownership & Leadership
C10: =Scorecard!B19 -> Gender & Inclusion Principles & Impact Measurement, Management & Monitoring
C11: =Scorecard!B20 -> Justice, Equity, Diversity & Inclusion
B13: =Scorecard!A24 -> III. Climate & Gender Integration | C13: =Scorecard!B25 -> Women as Agents of Change in Investment Thesis
C14: =Scorecard!B26 -> Women as Agents of Change in the Investment Process
C15: =Scorecard!B27 -> Eliminating Barriers to Women's Active Participation as Change Agents
C16: =Scorecard!B28 -> Transformational Change for Women
C17: =Scorecard!B29 -> Scaling Products and Services by/for Women
B19: =Scorecard!A33 -> IV. Organization & Team | C19: =Scorecard!B34 -> Track Record
C20: =Scorecard!B35 -> Team History, Cohesion and Complementarity & Culture
C21: =Scorecard!B36 -> Team Location & Composition & Diversity
C22: =Scorecard!B37 -> Alignment of Interest
B24: =Scorecard!A41 -> V. Fundraising, Fund Terms, Structure & Risk | C24: =Scorecard!B42 -> Fundraising Status
C25: =Scorecard!B43 -> Anchor Investor
C26: =Scorecard!B44 -> Fund Terms & Structure
C27: =Scorecard!B45 -> Financial Viability
C28: =Scorecard!B46 -> Risk Assessment
